Exception on /api/aprender/externo [POST]
Traceback (most recent call last):
  File "C:\Users\Tatiana\AppData\Local\Programs\Python\Python36-32\lib\site-packages\flask\app.py", line 1982, in wsgi_app
    response = self.full_dispatch_request()
  File "C:\Users\Tatiana\AppData\Local\Programs\Python\Python36-32\lib\site-packages\flask\app.py", line 1614, in full_dispatch_request
    rv = self.handle_user_exception(e)
  File "C:\Users\Tatiana\AppData\Local\Programs\Python\Python36-32\lib\site-packages\flask\app.py", line 1517, in handle_user_exception
    reraise(exc_type, exc_value, tb)
  File "C:\Users\Tatiana\AppData\Local\Programs\Python\Python36-32\lib\site-packages\flask\_compat.py", line 33, in reraise
    raise value
  File "C:\Users\Tatiana\AppData\Local\Programs\Python\Python36-32\lib\site-packages\flask\app.py", line 1612, in full_dispatch_request
    rv = self.dispatch_request()
  File "C:\Users\Tatiana\AppData\Local\Programs\Python\Python36-32\lib\site-packages\flask\app.py", line 1598, in dispatch_request
    return self.view_functions[rule.endpoint](**req.view_args)
  File "C:/Users/Tatiana/Documents/GitHub/Tatiana-bot/Tatiana-Bot/MainDeConocimiento.py", line 77, in aprender_externo
    return str(instancia.aprender_externo(nomb, parseo_de_json))
  File "C:\Users\Tatiana\Documents\GitHub\Tatiana-bot\Tatiana-Bot\Funciones\Gestion_de_conocimiento.py", line 160, in aprender_externo
    return self.creacion_de_memoria.aprender(Operaciones.aprender_externo(nombre, codigo))
AttributeError: module 'Funciones.Operaciones' has no attribute 'aprender_externo'
Exception on /api/aprender/externo [POST]
Traceback (most recent call last):
  File "C:\Users\Tatiana\AppData\Local\Programs\Python\Python36-32\lib\site-packages\flask\app.py", line 1982, in wsgi_app
    response = self.full_dispatch_request()
  File "C:\Users\Tatiana\AppData\Local\Programs\Python\Python36-32\lib\site-packages\flask\app.py", line 1614, in full_dispatch_request
    rv = self.handle_user_exception(e)
  File "C:\Users\Tatiana\AppData\Local\Programs\Python\Python36-32\lib\site-packages\flask\app.py", line 1517, in handle_user_exception
    reraise(exc_type, exc_value, tb)
  File "C:\Users\Tatiana\AppData\Local\Programs\Python\Python36-32\lib\site-packages\flask\_compat.py", line 33, in reraise
    raise value
  File "C:\Users\Tatiana\AppData\Local\Programs\Python\Python36-32\lib\site-packages\flask\app.py", line 1612, in full_dispatch_request
    rv = self.dispatch_request()
  File "C:\Users\Tatiana\AppData\Local\Programs\Python\Python36-32\lib\site-packages\flask\app.py", line 1598, in dispatch_request
    return self.view_functions[rule.endpoint](**req.view_args)
  File "C:/Users/Tatiana/Documents/GitHub/Tatiana-bot/Tatiana-Bot/MainDeConocimiento.py", line 77, in aprender_externo
    return str(instancia.aprender_externo(nomb, parseo_de_json))
  File "C:\Users\Tatiana\Documents\GitHub\Tatiana-bot\Tatiana-Bot\Funciones\Gestion_de_conocimiento.py", line 160, in aprender_externo
    return self.creacion_de_memoria.aprender(Operaciones.aprender_externo(nombre, codigo))
AttributeError: module 'Funciones.Operaciones' has no attribute 'aprender_externo'
Exception on /api/aprender/externo [POST]
Traceback (most recent call last):
  File "C:\Users\Tatiana\AppData\Local\Programs\Python\Python36-32\lib\site-packages\flask\app.py", line 1982, in wsgi_app
    response = self.full_dispatch_request()
  File "C:\Users\Tatiana\AppData\Local\Programs\Python\Python36-32\lib\site-packages\flask\app.py", line 1614, in full_dispatch_request
    rv = self.handle_user_exception(e)
  File "C:\Users\Tatiana\AppData\Local\Programs\Python\Python36-32\lib\site-packages\flask\app.py", line 1517, in handle_user_exception
    reraise(exc_type, exc_value, tb)
  File "C:\Users\Tatiana\AppData\Local\Programs\Python\Python36-32\lib\site-packages\flask\_compat.py", line 33, in reraise
    raise value
  File "C:\Users\Tatiana\AppData\Local\Programs\Python\Python36-32\lib\site-packages\flask\app.py", line 1612, in full_dispatch_request
    rv = self.dispatch_request()
  File "C:\Users\Tatiana\AppData\Local\Programs\Python\Python36-32\lib\site-packages\flask\app.py", line 1598, in dispatch_request
    return self.view_functions[rule.endpoint](**req.view_args)
  File "C:/Users/Tatiana/Documents/GitHub/Tatiana-bot/Tatiana-Bot/MainDeConocimiento.py", line 77, in aprender_externo
    return str(instancia.aprender_externo(nomb, parseo_de_json))
  File "C:\Users\Tatiana\Documents\GitHub\Tatiana-bot\Tatiana-Bot\Funciones\Gestion_de_conocimiento.py", line 160, in aprender_externo
    return self.creacion_de_memoria.aprender(Operaciones.aprender_externo(nombre, codigo))
AttributeError: module 'Funciones.Operaciones' has no attribute 'aprender_externo'
Exception on /api/aprender/externo [POST]
Traceback (most recent call last):
  File "C:\Users\Tatiana\AppData\Local\Programs\Python\Python36-32\lib\site-packages\flask\app.py", line 1982, in wsgi_app
    response = self.full_dispatch_request()
  File "C:\Users\Tatiana\AppData\Local\Programs\Python\Python36-32\lib\site-packages\flask\app.py", line 1614, in full_dispatch_request
    rv = self.handle_user_exception(e)
  File "C:\Users\Tatiana\AppData\Local\Programs\Python\Python36-32\lib\site-packages\flask\app.py", line 1517, in handle_user_exception
    reraise(exc_type, exc_value, tb)
  File "C:\Users\Tatiana\AppData\Local\Programs\Python\Python36-32\lib\site-packages\flask\_compat.py", line 33, in reraise
    raise value
  File "C:\Users\Tatiana\AppData\Local\Programs\Python\Python36-32\lib\site-packages\flask\app.py", line 1612, in full_dispatch_request
    rv = self.dispatch_request()
  File "C:\Users\Tatiana\AppData\Local\Programs\Python\Python36-32\lib\site-packages\flask\app.py", line 1598, in dispatch_request
    return self.view_functions[rule.endpoint](**req.view_args)
  File "C:/Users/Tatiana/Documents/GitHub/Tatiana-bot/Tatiana-Bot/MainDeConocimiento.py", line 77, in aprender_externo
    return str(instancia.aprender_externo(nomb, parseo_de_json))
  File "C:\Users\Tatiana\Documents\GitHub\Tatiana-bot\Tatiana-Bot\Funciones\Gestion_de_conocimiento.py", line 160, in aprender_externo
    return self.creacion_de_memoria.aprender(Operaciones.aprender_externo(nombre, codigo))
AttributeError: module 'Funciones.Operaciones' has no attribute 'aprender_externo'
Exception on /api/aprender/externo [POST]
Traceback (most recent call last):
  File "C:\Users\Tatiana\AppData\Local\Programs\Python\Python36-32\lib\site-packages\flask\app.py", line 1982, in wsgi_app
    response = self.full_dispatch_request()
  File "C:\Users\Tatiana\AppData\Local\Programs\Python\Python36-32\lib\site-packages\flask\app.py", line 1614, in full_dispatch_request
    rv = self.handle_user_exception(e)
  File "C:\Users\Tatiana\AppData\Local\Programs\Python\Python36-32\lib\site-packages\flask\app.py", line 1517, in handle_user_exception
    reraise(exc_type, exc_value, tb)
  File "C:\Users\Tatiana\AppData\Local\Programs\Python\Python36-32\lib\site-packages\flask\_compat.py", line 33, in reraise
    raise value
  File "C:\Users\Tatiana\AppData\Local\Programs\Python\Python36-32\lib\site-packages\flask\app.py", line 1612, in full_dispatch_request
    rv = self.dispatch_request()
  File "C:\Users\Tatiana\AppData\Local\Programs\Python\Python36-32\lib\site-packages\flask\app.py", line 1598, in dispatch_request
    return self.view_functions[rule.endpoint](**req.view_args)
  File "C:/Users/Tatiana/Documents/GitHub/Tatiana-bot/Tatiana-Bot/MainDeConocimiento.py", line 77, in aprender_externo
    return str(instancia.aprender_externo(nomb, parseo_de_json))
  File "C:\Users\Tatiana\Documents\GitHub\Tatiana-bot\Tatiana-Bot\Funciones\Gestion_de_conocimiento.py", line 160, in aprender_externo
    return self.creacion_de_memoria.aprender(Operaciones.aprender_externo(nombre, codigo))
AttributeError: module 'Funciones.Operaciones' has no attribute 'aprender_externo'
Exception on /api/aprender/externo [POST]
Traceback (most recent call last):
  File "C:\Users\Tatiana\AppData\Local\Programs\Python\Python36-32\lib\site-packages\flask\app.py", line 1982, in wsgi_app
    response = self.full_dispatch_request()
  File "C:\Users\Tatiana\AppData\Local\Programs\Python\Python36-32\lib\site-packages\flask\app.py", line 1614, in full_dispatch_request
    rv = self.handle_user_exception(e)
  File "C:\Users\Tatiana\AppData\Local\Programs\Python\Python36-32\lib\site-packages\flask\app.py", line 1517, in handle_user_exception
    reraise(exc_type, exc_value, tb)
  File "C:\Users\Tatiana\AppData\Local\Programs\Python\Python36-32\lib\site-packages\flask\_compat.py", line 33, in reraise
    raise value
  File "C:\Users\Tatiana\AppData\Local\Programs\Python\Python36-32\lib\site-packages\flask\app.py", line 1612, in full_dispatch_request
    rv = self.dispatch_request()
  File "C:\Users\Tatiana\AppData\Local\Programs\Python\Python36-32\lib\site-packages\flask\app.py", line 1598, in dispatch_request
    return self.view_functions[rule.endpoint](**req.view_args)
  File "C:/Users/Tatiana/Documents/GitHub/Tatiana-bot/Tatiana-Bot/MainDeConocimiento.py", line 77, in aprender_externo
    return str(instancia.aprender_externo(nomb, parseo_de_json))
  File "C:\Users\Tatiana\Documents\GitHub\Tatiana-bot\Tatiana-Bot\Funciones\Gestion_de_conocimiento.py", line 160, in aprender_externo
    return self.creacion_de_memoria.aprender(Operaciones.maria(nombre, codigo))
AttributeError: module 'Funciones.Operaciones' has no attribute 'maria'
